Workbook

Sheet Итоги
C2: Малаховка: аренда 700 ₽/м²
C4: Сценарий | D4: =Параметры!E5 -> Базовый
C7: Показатель, ₽ если не указано | F7: =Помесячно!O7 -> 46844 | G7: =Помесячно!P7 -> 46874 | H7: =Помесячно!Q7 -> 46905 | I7: =Помесячно!AC7 -> 47270
C8: Среднее число жителей | F8: =Помесячно!O13 -> 51 | G8: =Помесячно!P13 -> 53 | H8: =Помесячно!Q13 -> 54 | I8: =Помесячно!AC13 -> 54
C9: Загрузка | F9: =Помесячно!O14 -> 0.85 | G9: =Помесячно!P14 -> 0.88333333 | H9: =Помесячно!Q14 -> 0.9 | I9: =Помесячно!AC14 -> 0.9
C10: Платежи клиентов с НДС | F10: =Помесячно!O20 -> 5967000 | G10: =Помесячно!P20 -> 6407700 | H10: =Помесячно!Q20 -> 6318000 | I10: =Помесячно!AC20 -> 6697080
C11: Выручка без НДС | F11: =Помесячно!O26 -> 5682857.1 | G11: =Помесячно!P26 -> 6102571.4 | H11: =Помесячно!Q26 -> 6017142.9 | I11: =Помесячно!AC26 -> 6378171.4
C12: ФОТ с начислениями | F12: =Помесячно!O36 -> 3697680 | G12: =Помесячно!P36 -> 3801840 | H12: =Помесячно!Q36 -> 3697680 | I12: =Помесячно!AC36 -> 3956517.6
C13: Аренда | F13: =Помесячно!O43 -> 1290170 | G13: =Помесячно!P43 -> 1290170 | H13: =Помесячно!Q43 -> 1290170 | I13: =Помесячно!AC43 -> 1354678.5
C14: EBITDA | F14: =Помесячно!O46 -> -830562.86 | G14: =Помесячно!P46 -> -582805.57 | H14: =Помесячно!Q46 -> -547487.14 | I14: =Помесячно!AC46 -> -604411.47
C15: Резерв УСН | F15: =Помесячно!O47 -> 56828.571 | G15: =Помесячно!P47 -> 61025.714 | H15: =Помесячно!Q47 -> 60171.429 | I15: =Помесячно!AC47 -> 63781.714
C16: Денежный результат | F16: =Помесячно!O49 -> -887391.43 | G16: =Помесячно!P49 -> -643831.29 | H16: =Помесячно!Q49 -> -607658.57 | I16: =Помесячно!AC49 -> -668193.19
C17: Математический предел аренды | F17: =Помесячно!O56 -> 402778.57 | G17: =Помесячно!P56 -> 646338.71 | H17: =Помесячно!Q56 -> 682511.43 | I17: =Помесячно!AC56 -> 686485.31
C18: Аренда с целевым денежным запасом | F18: =Помесячно!O57 -> 102778.57 | G18: =Помесячно!P57 -> 346338.71 | H18: =Помесячно!Q57 -> 382511.43 | I18: =Помесячно!AC57 -> 386485.31
C21: Минимальный предел аренды М10–12 | F21: =MIN(Помесячно!O56:Q56) -> 402778.57
C22: Минимальный денежный результат М10–12 | F22: =MIN(Помесячно!O49:Q49) -> -887391.43
C23: Первый месяц положительного потока | F23: =IF(MAX(Помесячно!F62:AC62)=0,"Нет",MATCH(1,Помесячно!F62:AC62,0)) -> Нет
C24: Пиковый операционный дефицит | F24: =-MIN(0,Помесячно!F50:AC50) -> 24257899
C25: Минимум свободных денег | F25: =Параметры!D63+MIN(0,Помесячно!F50:AC50) -> -16257899
C26: Учтённые вложения без ремонта | F26: =Инвестиции!G31 -> 16806850
C27: В том числе депозит и запас | F27: =SUM(Инвестиции!G27:G28) -> 2930340
C28: Ликвидность при открытии | F28: =Инвестиции!G32 -> 8000000
C29: Средства без ремонта с ликвидностью | F29: =Инвестиции!G33 -> 24806850
C30: Минимум средств без ремонта и запаса | F30: =SUM(F24,F26) -> 41064749
C31: Накопленный поток учтённой части М24 | F31: =Помесячно!AC54 -> -41064749
C32: Возврат учтённых вложений (без ремонта) | F32: =IF(MAX(Помесячно!F63:AC63)=0,"Не достигнут за 24 месяца",MATCH(1,Помесячно!F63:AC63,0)) -> Не достигнут за 24 месяца
C33: Нехватка заданного резерва денег | F33: =MAX(0,-F25) -> 16257899
C35: Цель: месячный плюс к М10. Ремонт / реконструкция — отдельная смета.
C36: 60 мест и дата открытия — технические допущения. Право на запуск не подтверждено.
C37: Аренда полная с М1; 700 ₽/м² включает все налоги арендодателя.
C38: НДС 5% включен в цену после потери освобождения. УСН — консервативный резерв.
C39: План предполагает оплату месяца проживания в том же месяце без дебиторской задержки.
C40: Амортизация не списывает деньги; заемный платеж не уменьшает EBITDA.
C41: Допуск здания, спрос, кадровые графики и налоговые льготы проверяются до договора.
C44: До открытия: справочные платежи, не включены в бюджет
C45: Аренда за 3 месяца до открытия | F45: =Параметры!D41*3 -> 3870510
C46: Аренда за 6 месяцев до открытия | F46: =Параметры!D41*6 -> 7741020
C48: Начало аренды до открытия и срок подготовки пока неизвестны.
C49: Эти суммы добавляются к финансированию, если предусмотрены договором.
C51: Для проверки тарифа изменяйте цену базового случая на вкладке «Параметры».

Sheet Параметры
C2: Параметры модели
C4: Сценарий | D4: =Параметры!E5 -> Базовый
C5: Единый переключатель | D5: 1 | E5: =CHOOSE(D5,"Базовый","Неблагоприятный","Благоприятный") -> Базовый | F5: 1 — база; 2 — неблагоприятный; 3 — благоприятный
C10: Мест: расчетная гипотеза | D10: =CHOOSE($D$5,D11,D12,D13) -> 60 | F10: Вместимость не разрешена; требуется проект и обследование.
C11: Базовый | D11: 60
C12: Неблагоприятный | D12: 48
C13: Благоприятный | D13: 60
C15: Средняя цена, ₽/сутки, с НДС | D15: =CHOOSE($D$5,D16,D17,D18) -> 3900 | F15: Допущение. Цена реализованная после скидок.
C16: Базовый | D16: 3900
C17: Неблагоприятный | D17: 3300
C18: Благоприятный | D18: 4300
C20: Жителей при открытии | D20: =CHOOSE($D$5,D21,D22,D23) -> 12 | F20: Допущение; не подтвержденные бронирования.
C21: Базовый | D21: 12
C22: Неблагоприятный | D22: 8
C23: Благоприятный | D23: 18
C25: Множитель зарплат | D25: =CHOOSE($D$5,D26,D27,D28) -> 1 | F25: Неблагоприятный сценарий: +10%.
C26: Базовый | D26: 1
C27: Неблагоприятный | D27: 1.1
C28: Благоприятный | D28: 1
C30: Множитель переменных расходов | D30: =CHOOSE($D$5,D31,D32,D33) -> 1 | F30: Неблагоприятный сценарий: +15%.
C31: Базовый | D31: 1
C32: Неблагоприятный | D32: 1.15
C33: Благоприятный | D33: 1
C40: Техническая дата открытия | D40: 46569 | F40: Не обещание запуска. Введите первое число месяца.
C41: Полная аренда, ₽/мес | D41: =D64*D65 -> 1290170 | F41: Общая площадь × ставка. Включая все налоги арендодателя.
C42: Ставка ухода, gross, ₽/FTE | D42: 80000 | F42: Допущение; HH в Малаховке: от 70 400 ₽ gross.
C43: Расчетная норма часов/FTE | D43: 160 | F43: График проверяется по ТК и фактическому календарю.
C44: Резерв замещения персонала | D44: 0.15 | F44: Отпуска, болезни и обучение; допущение.
C45: Начисления на зарплату | D45: 0.302 | F45: 30% + условные 0,2% травматизма; без льготы МСП.
C46: Переменные, ₽/житель-день | D46: 530 | F46: Продукты 380 + стирка 60 + гигиена 90; допущение.
C47: Питание работников, ₽/день | D47: 3500 | F47: Отдельный бюджет даже при малой загрузке.
C48: Прочие постоянные, ₽/мес | D48: 550000 | F48: 150 ресурсы; 180 реклама; 100 медпартнер; 35 учет/IT; 30 отходы; 40 сервис/обслуживание; 15 страхование (тыс. ₽).
C49: Эквайринг от платежей | D49: 0.01 | F49: Допущение.
C50: Индексация зарплат с М13 | D50: 0.07 | F50: Допущение; применяется ко всем gross-ставкам.
C51: Индексация цены с М13 | D51: 0.06 | F51: Допущение.
C52: Индексация прочих затрат с М13 | D52: 0.06 | F52: Переменные, питание работников, постоянные; допущение.
C53: Индексация аренды с М13 | D53: 0.05 | F53: Гипотеза переговоров.
... C76: Маркетинг в составе постоянных | D76: 180000 | F76: Для ориентира стоимости обращения; уже включено в строку 48.
C78: Синие значения на желтом фоне изменяются. Зеленые — ссылки; черные — формулы.
C80: Месяц после открытия | F80: 1 | G80: 2 | H80: 3 | I80: 4 | J80: 5 | K80: 6 | L80: 7 | M80: 8 | N80: 9 | O80: 10 | P80: 11 | Q80: 12 | R80: 13 | S80: 14 | T80: 15 | U80: 16 | V80: 17 | W80: 18 | X80: 19 | Y80: 20 | Z80: 21 | AA80: 22 | AB80: 23 | AC80: 24
...

Sheet Помесячно
C2: Прогноз на 24 календарных месяца
C4: Сценарий | F4: =Параметры!E5 -> Базовый
C6: Месяц после открытия | F6: =1 -> 1 | G6: =2 -> 2 | H6: =3 -> 3 | I6: =4 -> 4 | J6: =5 -> 5 | K6: =6 -> 6 | L6: =7 -> 7 | M6: =8 -> 8 | N6: =9 -> 9 | O6: =10 -> 10 | P6: =11 -> 11 | Q6: =12 -> 12 | R6: =13 -> 13 | S6: =14 -> 14 | T6: =15 -> 15 | U6: =16 -> 16 | V6: =17 -> 17 | W6: =18 -> 18 | X6: =19 -> 19 | Y6: =20 -> 20 | Z6: =21 -> 21 | AA6: =22 -> 22 | AB6: =23 -> 23 | AC6: =24 -> 24
C7: Календарный месяц | F7: =EDATE(Параметры!$D$40,F6-1) -> 46569 | G7: =EDATE(Параметры!$D$40,G6-1) -> 46600 | H7: =EDATE(Параметры!$D$40,H6-1) -> 46631 | I7: =EDATE(Параметры!$D$40,I6-1) -> 46661 | J7: =EDATE(Параметры!$D$40,J6-1) -> 46692 | K7: =EDATE(Параметры!$D$40,K6-1) -> 46722 | L7: =EDATE(Параметры!$D$40,L6-1) -> 46753 | M7: =EDATE(Параметры!$D$40,M6-1) -> 46784 | ... AC7: =EDATE(Параметры!$D$40,AC6-1) -> 47270
C8: Календарных дней | F8: =DAY(EOMONTH(F7,0)) -> 31 | G8: =DAY(EOMONTH(G7,0)) -> 31 | H8: =DAY(EOMONTH(H7,0)) -> 30 | I8: =DAY(EOMONTH(I7,0)) -> 31 | J8: =DAY(EOMONTH(J7,0)) -> 30 | K8: =DAY(EOMONTH(K7,0)) -> 31 | L8: =DAY(EOMONTH(L7,0)) -> 31 | M8: =DAY(EOMONTH(M7,0)) -> 29 | ... AC8: =DAY(EOMONTH(AC7,0)) -> 30
C9: Календарный год | F9: =YEAR(F7) -> 2027 | G9: =YEAR(G7) -> 2027 | H9: =YEAR(H7) -> 2027 | I9: =YEAR(I7) -> 2027 | J9: =YEAR(J7) -> 2027 | K9: =YEAR(K7) -> 2027 | L9: =YEAR(L7) -> 2028 | M9: =YEAR(M7) -> 2028 | ... AC9: =YEAR(AC7) -> 2029
C10: Расчетная вместимость | F10: =Параметры!$D$10 -> 60 | G10: =Параметры!$D$10 -> 60 | H10: =Параметры!$D$10 -> 60 | I10: =Параметры!$D$10 -> 60 | J10: =Параметры!$D$10 -> 60 | K10: =Параметры!$D$10 -> 60 | L10: =Параметры!$D$10 -> 60 | M10: =Параметры!$D$10 -> 60 | ... AC10: =Параметры!$D$10 -> 60
C11: Жителей на начало | F11: =Параметры!$D$20 -> 12 | G11: =F12 -> 18 | H11: =G12 -> 24 | I11: =H12 -> 30 | J11: =I12 -> 34 | K11: =J12 -> 38 | L11: =K12 -> 42 | M11: =L12 -> 45 | N11: =M12 -> 48 | ... AC11: =AB12 -> 54
C12: Жителей на конец | F12: =MIN(F10,Параметры!F82) -> 18 | G12: =MIN(G10,Параметры!G82) -> 24 | H12: =MIN(H10,Параметры!H82) -> 30 | I12: =MIN(I10,Параметры!I82) -> 34 | J12: =MIN(J10,Параметры!J82) -> 38 | K12: =MIN(K10,Параметры!K82) -> 42 | L12: =MIN(L10,Параметры!L82) -> 45 | M12: =MIN(M10,Параметры!M82) -> 48 | ... AC12: =MIN(AC10,Параметры!AC82) -> 54
C13: Среднее число жителей | F13: =AVERAGE(F11:F12) -> 15 | G13: =AVERAGE(G11:G12) -> 21 | H13: =AVERAGE(H11:H12) -> 27 | I13: =AVERAGE(I11:I12) -> 32 | J13: =AVERAGE(J11:J12) -> 36 | K13: =AVERAGE(K11:K12) -> 40 | L13: =AVERAGE(L11:L12) -> 43.5 | M13: =AVERAGE(M11:M12) -> 46.5 | ... AC13: =AVERAGE(AC11:AC12) -> 54
C14: Средняя загрузка | F14: =F13/F10 -> 0.25 | G14: =G13/G10 -> 0.35 | H14: =H13/H10 -> 0.45 | I14: =I13/I10 -> 0.53333333 | J14: =J13/J10 -> 0.6 | K14: =K13/K10 -> 0.66666667 | L14: =L13/L10 -> 0.725 | M14: =M13/M10 -> 0.775 | ... AC14: =AC13/AC10 -> 0.9
C15: Максимум жителей для штата | F15: =MAX(F11:F12) -> 18 | G15: =MAX(G11:G12) -> 24 | H15: =MAX(H11:H12) -> 30 | I15: =MAX(I11:I12) -> 34 | J15: =MAX(J11:J12) -> 38 | K15: =MAX(K11:K12) -> 42 | L15: =MAX(L11:L12) -> 45 | M15: =MAX(M11:M12) -> 48 | ... AC15: =MAX(AC11:AC12) -> 54
C16: Выбытия, гипотеза | F16: =F11*Параметры!$D$54 -> 0.6 | G16: =G11*Параметры!$D$54 -> 0.9 | H16: =H11*Параметры!$D$54 -> 1.2 | I16: =I11*Параметры!$D$54 -> 1.5 | J16: =J11*Параметры!$D$54 -> 1.7 | K16: =K11*Параметры!$D$54 -> 1.9 | L16: =L11*Параметры!$D$54 -> 2.1 | M16: =M11*Параметры!$D$54 -> 2.25 | ... AC16: =AC11*Параметры!$D$54 -> 2.7
C17: Необходимые заселения | F17: =F12-F11+F16 -> 6.6 | G17: =G12-G11+G16 -> 6.9 | H17: =H12-H11+H16 -> 7.2 | I17: =I12-I11+I16 -> 5.5 | J17: =J12-J11+J16 -> 5.7 | K17: =K12-K11+K16 -> 5.9 | L17: =L12-L11+L16 -> 5.1 | M17: =M12-M11+M16 -> 5.25 | ... AC17: =AC12-AC11+AC16 -> 2.7
C18: Необходимые обращения | F18: =F17/Параметры!$D$75 -> 66 | G18: =G17/Параметры!$D$75 -> 69 | H18: =H17/Параметры!$D$75 -> 72 | I18: =I17/Параметры!$D$75 -> 55 | J18: =J17/Параметры!$D$75 -> 57 | K18: =K17/Параметры!$D$75 -> 59 | L18: =L17/Параметры!$D$75 -> 51 | M18: =M17/Параметры!$D$75 -> 52.5 | ... AC18: =AC17/Параметры!$D$75 -> 27
C19: Цена с НДС, ₽/сутки | F19: =Параметры!$D$15*(1+Параметры!$D$51)^INT((F6-1)/12) -> 3900 | G19: =Параметры!$D$15*(1+Параметры!$D$51)^INT((G6-1)/12) -> 3900 | H19: =Параметры!$D$15*(1+Параметры!$D$51)^INT((H6-1)/12) -> 3900 | I19: =Параметры!$D$15*(1+Параметры!$D$51)^INT((I6-1)/12) -> 3900 | J19: =Параметры!$D$15*(1+Параметры!$D$51)^INT((J6-1)/12) -> 3900 | K19: =Параметры!$D$15*(1+Параметры!$D$51)^INT((K6-1)/12) -> 3900 | L19: =Параметры!$D$15*(1+Параметры!$D$51)^INT((L6-1)/12) -> 3900 | M19: =Параметры!$D$15*(1+Параметры!$D$51)^INT((M6-1)/12) -> 3900 | ... AC19: =Параметры!$D$15*(1+Параметры!$D$51)^INT((AC6-1)/12) -> 4134
C20: Платежи клиентов с НДС | F20: =F13*F8*F19 -> 1813500 | G20: =G13*G8*G19 -> 2538900 | H20: =H13*H8*H19 -> 3159000 | I20: =I13*I8*I19 -> 3868800 | J20: =J13*J8*J19 -> 4212000 | K20: =K13*K8*K19 -> 4836000 | L20: =L13*L8*L19 -> 5259150 | M20: =M13*M8*M19 -> 5259150 | ... AC20: =AC13*AC8*AC19 -> 6697080
C21: Другие доходы для порога НДС | F21: =Параметры!$D$62 -> 0 | G21: =Параметры!$D$62 -> 0 | H21: =Параметры!$D$62 -> 0 | I21: =Параметры!$D$62 -> 0 | J21: =Параметры!$D$62 -> 0 | K21: =Параметры!$D$62 -> 0 | L21: =Параметры!$D$62 -> 0 | M21: =Параметры!$D$62 -> 0 | ... AC21: =Параметры!$D$62 -> 0
C22: Доход оператора прошлого года | F22: =Параметры!$D$60 -> 0 | G22: =IF(G9=F9,F22,F27) -> 0 | H22: =IF(H9=G9,G22,G27) -> 0 | I22: =IF(I9=H9,H22,H27) -> 0 | J22: =IF(J9=I9,I22,I27) -> 0 | K22: =IF(K9=J9,J22,J27) -> 0 | L22: =IF(L9=K9,K22,K27) -> 20428200 | M22: =IF(M9=L9,L22,L27) -> 20428200 | N22: =IF(N9=M9,M22,M27) -> 20428200 | ... AC22: =IF(AC9=AB9,AB22,AB27) -> 72581451
C23: Доход текущего года до месяца | F23: =Параметры!$D$61 -> 0 | G23: =IF(G9=F9,F27,0) -> 1813500 | H23: =IF(H9=G9,G27,0) -> 4352400 | I23: =IF(I9=H9,H27,0) -> 7511400 | J23: =IF(J9=I9,I27,0) -> 11380200 | K23: =IF(K9=J9,J27,0) -> 15592200 | L23: =IF(L9=K9,K27,0) -> 0 | M23: =IF(M9=L9,L27,0) -> 5008714.3 | N23: =IF(N9=M9,M27,0) -> 10017429 | ... AC23: =IF(AC9=AB9,AB27,0) -> 32103463
C24: НДС включен: 1 / нет: 0 | F24: =IF(Параметры!$D$57=1,0,IF(OR(F22>Параметры!$D$55,F23>Параметры!$D$55),1,0)) -> 0 | G24: =IF(Параметры!$D$57=1,0,IF(OR(G22>Параметры!$D$55,G23>Параметры!$D$55),1,0)) -> 0 | H24: =IF(Параметры!$D$57=1,0,IF(OR(H22>Параметры!$D$55,H23>Параметры!$D$55),1,0)) -> 0 | I24: =IF(Параметры!$D$57=1,0,IF(OR(I22>Параметры!$D$55,I23>Параметры!$D$55),1,0)) -> 0 | J24: =IF(Параметры!$D$57=1,0,IF(OR(J22>Параметры!$D$55,J23>Параметры!$D$55),1,0)) -> 0 | K24: =IF(Параметры!$D$57=1,0,IF(OR(K22>Параметры!$D$55,K23>Параметры!$D$55),1,0)) -> 0 | L24: =IF(Параметры!$D$57=1,0,IF(OR(L22>Параметры!$D$55,L23>Параметры!$D$55),1,0)) -> 1 | M24: =IF(Параметры!$D$57=1,0,IF(OR(M22>Параметры!$D$55,M23>Параметры!$D$55),1,0)) -> 1 | ... AC24: =IF(Параметры!$D$57=1,0,IF(OR(AC22>Параметры!$D$55,AC23>Параметры!$D$55),1,0)) -> 1
C25: НДС в клиентских платежах | F25: =F20*F24*Параметры!$D$56/(1+Параметры!$D$56) -> 0 | G25: =G20*G24*Параметры!$D$56/(1+Параметры!$D$56) -> 0 | H25: =H20*H24*Параметры!$D$56/(1+Параметры!$D$56) -> 0 | I25: =I20*I24*Параметры!$D$56/(1+Параметры!$D$56) -> 0 | J25: =J20*J24*Параметры!$D$56/(1+Параметры!$D$56) -> 0 | K25: =K20*K24*Параметры!$D$56/(1+Параметры!$D$56) -> 0 | L25: =L20*L24*Параметры!$D$56/(1+Параметры!$D$56) -> 250435.71 | M25: =M20*M24*Параметры!$D$56/(1+Параметры!$D$56) -> 250435.71 | ... AC25: =AC20*AC24*Параметры!$D$56/(1+Параметры!$D$56) -> 318908.57
C26: Выручка без НДС | F26: =F20-F25 -> 1813500 | G26: =G20-G25 -> 2538900 | H26: =H20-H25 -> 3159000 | I26: =I20-I25 -> 3868800 | J26: =J20-J25 -> 4212000 | K26: =K20-K25 -> 4836000 | L26: =L20-L25 -> 5008714.3 | M26: =M20-M25 -> 5008714.3 | ... AC26: =AC20-AC25 -> 6378171.4
C27: Доход текущего года на конец | F27: =SUM(F23,F26,F21) -> 1813500 | G27: =SUM(G23,G26,G21) -> 4352400 | H27: =SUM(H23,H26,H21) -> 7511400 | I27: =SUM(I23,I26,I21) -> 11380200 | J27: =SUM(J23,J26,J21) -> 15592200 | K27: =SUM(K23,K26,K21) -> 20428200 | L27: =SUM(L23,L26,L21) -> 5008714.3 | M27: =SUM(M23,M26,M21) -> 10017429 | ... AC27: =SUM(AC23,AC26,AC21) -> 38481634
C28: Дневных постов ухода | F28: =MAX(Параметры!$D$70,ROUNDUP(F15/Параметры!$D$71,0),ROUNDUP(F15/Параметры!$D$72,0)) -> 2 | G28: =MAX(Параметры!$D$70,ROUNDUP(G15/Параметры!$D$71,0),ROUNDUP(G15/Параметры!$D$72,0)) -> 3 | H28: =MAX(Параметры!$D$70,ROUNDUP(H15/Параметры!$D$71,0),ROUNDUP(H15/Параметры!$D$72,0)) -> 3 | I28: =MAX(Параметры!$D$70,ROUNDUP(I15/Параметры!$D$71,0),ROUNDUP(I15/Параметры!$D$72,0)) -> 4 | J28: =MAX(Параметры!$D$70,ROUNDUP(J15/Параметры!$D$71,0),ROUNDUP(J15/Параметры!$D$72,0)) -> 4 | K28: =MAX(Параметры!$D$70,ROUNDUP(K15/Параметры!$D$71,0),ROUNDUP(K15/Параметры!$D$72,0)) -> 5 | L28: =MAX(Параметры!$D$70,ROUNDUP(L15/Параметры!$D$71,0),ROUNDUP(L15/Параметры!$D$72,0)) -> 5 | M28: =MAX(Параметры!$D$70,ROUNDUP(M15/Параметры!$D$71,0),ROUNDUP(M15/Параметры!$D$72,0)) -> 5 | ... AC28: =MAX(Параметры!$D$70,ROUNDUP(AC15/Параметры!$D$71,0),ROUNDUP(AC15/Параметры!$D$72,0)) -> 6
C29: Ночных постов ухода | F29: =MAX(Параметры!$D$70,ROUNDUP(F15/Параметры!$D$71,0),ROUNDUP(F15/Параметры!$D$73,0)) -> 2 | G29: =MAX(Параметры!$D$70,ROUNDUP(G15/Параметры!$D$71,0),ROUNDUP(G15/Параметры!$D$73,0)) -> 2 | H29: =MAX(Параметры!$D$70,ROUNDUP(H15/Параметры!$D$71,0),ROUNDUP(H15/Параметры!$D$73,0)) -> 2 | I29: =MAX(Параметры!$D$70,ROUNDUP(I15/Параметры!$D$71,0),ROUNDUP(I15/Параметры!$D$73,0)) -> 2 | J29: =MAX(Параметры!$D$70,ROUNDUP(J15/Параметры!$D$71,0),ROUNDUP(J15/Параметры!$D$73,0)) -> 2 | K29: =MAX(Параметры!$D$70,ROUNDUP(K15/Параметры!$D$71,0),ROUNDUP(K15/Параметры!$D$73,0)) -> 3 | L29: =MAX(Параметры!$D$70,ROUNDUP(L15/Параметры!$D$71,0),ROUNDUP(L15/Параметры!$D$73,0)) -> 3 | M29: =MAX(Параметры!$D$70,ROUNDUP(M15/Параметры!$D$71,0),ROUNDUP(M15/Параметры!$D$73,0)) -> 3 | ... AC29: =MAX(Параметры!$D$70,ROUNDUP(AC15/Параметры!$D$71,0),ROUNDUP(AC15/Параметры!$D$73,0)) -> 3
C30: FTE ухода с резервом | F30: =ROUNDUP(SUM(F28:F29)*Параметры!$D$74*F8/Параметры!$D$43*(1+Параметры!$D$44),0) -> 11 | G30: =ROUNDUP(SUM(G28:G29)*Параметры!$D$74*G8/Параметры!$D$43*(1+Параметры!$D$44),0) -> 14 | H30: =ROUNDUP(SUM(H28:H29)*Параметры!$D$74*H8/Параметры!$D$43*(1+Параметры!$D$44),0) -> 13 | I30: =ROUNDUP(SUM(I28:I29)*Параметры!$D$74*I8/Параметры!$D$43*(1+Параметры!$D$44),0) -> 17 | J30: =ROUNDUP(SUM(J28:J29)*Параметры!$D$74*J8/Параметры!$D$43*(1+Параметры!$D$44),0) -> 16 | K30: =ROUNDUP(SUM(K28:K29)*Параметры!$D$74*K8/Параметры!$D$43*(1+Параметры!$D$44),0) -> 22 | L30: =ROUNDUP(SUM(L28:L29)*Параметры!$D$74*L8/Параметры!$D$43*(1+Параметры!$D$44),0) -> 22 | M30: =ROUNDUP(SUM(M28:M29)*Параметры!$D$74*M8/Параметры!$D$43*(1+Параметры!$D$44),0) -> 21 | ... AC30: =ROUNDUP(SUM(AC28:AC29)*Параметры!$D$74*AC8/Параметры!$D$43*(1+Параметры!$D$44),0) -> 24
C31: Gross/FTE ухода, ₽ | F31: =Параметры!$D$42*Параметры!$D$25*(1+Параметры!$D$50)^INT((F6-1)/12) -> 80000 | G31: =Параметры!$D$42*Параметры!$D$25*(1+Параметры!$D$50)^INT((G6-1)/12) -> 80000 | H31: =Параметры!$D$42*Параметры!$D$25*(1+Параметры!$D$50)^INT((H6-1)/12) -> 80000 | I31: =Параметры!$D$42*Параметры!$D$25*(1+Параметры!$D$50)^INT((I6-1)/12) -> 80000 | J31: =Параметры!$D$42*Параметры!$D$25*(1+Параметры!$D$50)^INT((J6-1)/12) -> 80000 | K31: =Параметры!$D$42*Параметры!$D$25*(1+Параметры!$D$50)^INT((K6-1)/12) -> 80000 | L31: =Параметры!$D$42*Параметры!$D$25*(1+Параметры!$D$50)^INT((L6-1)/12) -> 80000 | M31: =Параметры!$D$42*Параметры!$D$25*(1+Параметры!$D$50)^INT((M6-1)/12) -> 80000 | ... AC31: =Параметры!$D$42*Параметры!$D$25*(1+Параметры!$D$50)^INT((AC6-1)/12) -> 85600
C32: Gross персонала ухода | F32: =F30*F31 -> 880000 | G32: =G30*G31 -> 1120000 | H32: =H30*H31 -> 1040000 | I32: =I30*I31 -> 1360000 | J32: =J30*J31 -> 1280000 | K32: =K30*K31 -> 1760000 | L32: =L30*L31 -> 1760000 | M32: =M30*M31 -> 1680000 | ... AC32: =AC30*AC31 -> 2054400
C33: Gross вспомогательного штата | F33: =Штат!$F$17*Параметры!$D$25*(1+Параметры!$D$50)^INT((F6-1)/12) -> 920000 | G33: =Штат!$F$17*Параметры!$D$25*(1+Параметры!$D$50)^INT((G6-1)/12) -> 920000 | H33: =Штат!$F$17*Параметры!$D$25*(1+Параметры!$D$50)^INT((H6-1)/12) -> 920000 | I33: =Штат!$F$17*Параметры!$D$25*(1+Параметры!$D$50)^INT((I6-1)/12) -> 920000 | J33: =Штат!$F$17*Параметры!$D$25*(1+Параметры!$D$50)^INT((J6-1)/12) -> 920000 | K33: =Штат!$F$17*Параметры!$D$25*(1+Параметры!$D$50)^INT((K6-1)/12) -> 920000 | L33: =Штат!$F$17*Параметры!$D$25*(1+Параметры!$D$50)^INT((L6-1)/12) -> 920000 | M33: =Штат!$F$17*Параметры!$D$25*(1+Параметры!$D$50)^INT((M6-1)/12) -> 920000 | ... AC33: =Штат!$F$17*Параметры!$D$25*(1+Параметры!$D$50)^INT((AC6-1)/12) -> 984400
C34: Совокупный gross | F34: =SUM(F32:F33) -> 1800000 | G34: =SUM(G32:G33) -> 2040000 | H34: =SUM(H32:H33) -> 1960000 | I34: =SUM(I32:I33) -> 2280000 | J34: =SUM(J32:J33) -> 2200000 | K34: =SUM(K32:K33) -> 2680000 | L34: =SUM(L32:L33) -> 2680000 | M34: =SUM(M32:M33) -> 2600000 | ... AC34: =SUM(AC32:AC33) -> 3038800
C35: Страховые начисления | F35: =F34*Параметры!$D$45 -> 543600 | G35: =G34*Параметры!$D$45 -> 616080 | H35: =H34*Параметры!$D$45 -> 591920 | I35: =I34*Параметры!$D$45 -> 688560 | J35: =J34*Параметры!$D$45 -> 664400 | K35: =K34*Параметры!$D$45 -> 809360 | L35: =L34*Параметры!$D$45 -> 809360 | M35: =M34*Параметры!$D$45 -> 785200 | ... AC35: =AC34*Параметры!$D$45 -> 917717.6
C36: ФОТ с начислениями | F36: =SUM(F34:F35) -> 2343600 | G36: =SUM(G34:G35) -> 2656080 | H36: =SUM(H34:H35) -> 2551920 | I36: =SUM(I34:I35) -> 2968560 | J36: =SUM(J34:J35) -> 2864400 | K36: =SUM(K34:K35) -> 3489360 | L36: =SUM(L34:L35) -> 3489360 | M36: =SUM(M34:M35) -> 3385200 | ... AC36: =SUM(AC34:AC35) -> 3956517.6
C37: Переменные, ₽/житель-день | F37: =Параметры!$D$46*Параметры!$D$30*(1+Параметры!$D$52)^INT((F6-1)/12) -> 530 | G37: =Параметры!$D$46*Параметры!$D$30*(1+Параметры!$D$52)^INT((G6-1)/12) -> 530 | H37: =Параметры!$D$46*Параметры!$D$30*(1+Параметры!$D$52)^INT((H6-1)/12) -> 530 | I37: =Параметры!$D$46*Параметры!$D$30*(1+Параметры!$D$52)^INT((I6-1)/12) -> 530 | J37: =Параметры!$D$46*Параметры!$D$30*(1+Параметры!$D$52)^INT((J6-1)/12) -> 530 | K37: =Параметры!$D$46*Параметры!$D$30*(1+Параметры!$D$52)^INT((K6-1)/12) -> 530 | L37: =Параметры!$D$46*Параметры!$D$30*(1+Параметры!$D$52)^INT((L6-1)/12) -> 530 | M37: =Параметры!$D$46*Параметры!$D$30*(1+Параметры!$D$52)^INT((M6-1)/12) -> 530 | ... AC37: =Параметры!$D$46*Параметры!$D$30*(1+Параметры!$D$52)^INT((AC6-1)/12) -> 561.8
C38: Питание, стирка, гигиена жителей | F38: =F13*F8*F37 -> 246450 | G38: =G13*G8*G37 -> 345030 | H38: =H13*H8*H37 -> 429300 | I38: =I13*I8*I37 -> 525760 | J38: =J13*J8*J37 -> 572400 | K38: =K13*K8*K37 -> 657200 | L38: =L13*L8*L37 -> 714705 | M38: =M13*M8*M37 -> 714705 | ... AC38: =AC13*AC8*AC37 -> 910116
C39: Питание работников | F39: =Параметры!$D$47*F8*(1+Параметры!$D$52)^INT((F6-1)/12) -> 108500 | G39: =Параметры!$D$47*G8*(1+Параметры!$D$52)^INT((G6-1)/12) -> 108500 | H39: =Параметры!$D$47*H8*(1+Параметры!$D$52)^INT((H6-1)/12) -> 105000 | I39: =Параметры!$D$47*I8*(1+Параметры!$D$52)^INT((I6-1)/12) -> 108500 | J39: =Параметры!$D$47*J8*(1+Параметры!$D$52)^INT((J6-1)/12) -> 105000 | K39: =Параметры!$D$47*K8*(1+Параметры!$D$52)^INT((K6-1)/12) -> 108500 | L39: =Параметры!$D$47*L8*(1+Параметры!$D$52)^INT((L6-1)/12) -> 108500 | M39: =Параметры!$D$47*M8*(1+Параметры!$D$52)^INT((M6-1)/12) -> 101500 | ... AC39: =Параметры!$D$47*AC8*(1+Параметры!$D$52)^INT((AC6-1)/12) -> 111300
C40: Прочие постоянные и доп. медсестра | F40: =(Параметры!$D$48+Параметры!$D$68)*(1+Параметры!$D$52)^INT((F6-1)/12) -> 550000 | G40: =(Параметры!$D$48+Параметры!$D$68)*(1+Параметры!$D$52)^INT((G6-1)/12) -> 550000 | H40: =(Параметры!$D$48+Параметры!$D$68)*(1+Параметры!$D$52)^INT((H6-1)/12) -> 550000 | I40: =(Параметры!$D$48+Параметры!$D$68)*(1+Параметры!$D$52)^INT((I6-1)/12) -> 550000 | J40: =(Параметры!$D$48+Параметры!$D$68)*(1+Параметры!$D$52)^INT((J6-1)/12) -> 550000 | K40: =(Параметры!$D$48+Параметры!$D$68)*(1+Параметры!$D$52)^INT((K6-1)/12) -> 550000 | L40: =(Параметры!$D$48+Параметры!$D$68)*(1+Параметры!$D$52)^INT((L6-1)/12) -> 550000 | M40: =(Параметры!$D$48+Параметры!$D$68)*(1+Параметры!$D$52)^INT((M6-1)/12) -> 550000 | ... AC40: =(Параметры!$D$48+Параметры!$D$68)*(1+Параметры!$D$52)^INT((AC6-1)/12) -> 583000
C41: Эквайринг | F41: =F20*Параметры!$D$49 -> 18135 | G41: =G20*Параметры!$D$49 -> 25389 | H41: =H20*Параметры!$D$49 -> 31590 | I41: =I20*Параметры!$D$49 -> 38688 | J41: =J20*Параметры!$D$49 -> 42120 | K41: =K20*Параметры!$D$49 -> 48360 | L41: =L20*Параметры!$D$49 -> 52591.5 | M41: =M20*Параметры!$D$49 -> 52591.5 | ... AC41: =AC20*Параметры!$D$49 -> 66970.8
C42: Доля полной аренды | F42: =IF(Параметры!$D$69=0,1,IF(F6<=3,0,IF(F6<=6,0.5,1))) -> 1 | G42: =IF(Параметры!$D$69=0,1,IF(G6<=3,0,IF(G6<=6,0.5,1))) -> 1 | H42: =IF(Параметры!$D$69=0,1,IF(H6<=3,0,IF(H6<=6,0.5,1))) -> 1 | I42: =IF(Параметры!$D$69=0,1,IF(I6<=3,0,IF(I6<=6,0.5,1))) -> 1 | J42: =IF(Параметры!$D$69=0,1,IF(J6<=3,0,IF(J6<=6,0.5,1))) -> 1 | K42: =IF(Параметры!$D$69=0,1,IF(K6<=3,0,IF(K6<=6,0.5,1))) -> 1 | L42: =IF(Параметры!$D$69=0,1,IF(L6<=3,0,IF(L6<=6,0.5,1))) -> 1 | M42: =IF(Параметры!$D$69=0,1,IF(M6<=3,0,IF(M6<=6,0.5,1))) -> 1 | ... AC42: =IF(Параметры!$D$69=0,1,IF(AC6<=3,0,IF(AC6<=6,0.5,1))) -> 1
C43: Аренда с НДС арендодателя | F43: =Параметры!$D$41*F42*(1+Параметры!$D$53)^INT((F6-1)/12) -> 1290170 | G43: =Параметры!$D$41*G42*(1+Параметры!$D$53)^INT((G6-1)/12) -> 1290170 | H43: =Параметры!$D$41*H42*(1+Параметры!$D$53)^INT((H6-1)/12) -> 1290170 | I43: =Параметры!$D$41*I42*(1+Параметры!$D$53)^INT((I6-1)/12) -> 1290170 | J43: =Параметры!$D$41*J42*(1+Параметры!$D$53)^INT((J6-1)/12) -> 1290170 | K43: =Параметры!$D$41*K42*(1+Параметры!$D$53)^INT((K6-1)/12) -> 1290170 | L43: =Параметры!$D$41*L42*(1+Параметры!$D$53)^INT((L6-1)/12) -> 1290170 | M43: =Параметры!$D$41*M42*(1+Параметры!$D$53)^INT((M6-1)/12) -> 1290170 | ... AC43: =Параметры!$D$41*AC42*(1+Параметры!$D$53)^INT((AC6-1)/12) -> 1354678.5
...

Sheet Штат
C2: Вспомогательный штат
C4: Сценарий | D4: =Параметры!E5 -> Базовый
C7: Должность | D7: FTE | E7: Gross/FTE, ₽ | F7: Gross/месяц, ₽
C8: Управляющий | D8: 1 | E8: 130000 | F8: =D8*E8 -> 130000 | I8: Опора: местная вакансия 70 400 ₽ gross для ухода.
C9: Руководитель ухода | D9: 1 | E9: 95000 | F9: =D9*E9 -> 95000 | I9: https://teplye-besedy.ru/about/vacancies/
C10: Администратор | D10: 1 | E10: 90000 | F10: =D10*E10 -> 90000 | I10: https://hh.ru/vacancies/administrator-otdeleniya/polniy_den
C11: Повара | D11: 2.5 | E11: 80000 | F11: =D11*E11 -> 200000
C12: Кухонные работники | D12: 2.5 | E12: 60000 | F12: =D12*E12 -> 150000 | I12: Gross — до НДФЛ. Net зарплат здесь не смешивается с gross.
C13: Уборка | D13: 3 | E13: 60000 | F13: =D13*E13 -> 180000
C14: Досуг | D14: 0.5 | E14: 70000 | F14: =D14*E14 -> 35000
C15: Техническое обслуживание | D15: 0.5 | E15: 80000 | F15: =D15*E15 -> 40000
C17: Итого вспомогательный штат | D17: =SUM(D8:D15) -> 12 | F17: =SUM(F8:F15) -> 920000
C20: Все ставки — бюджетные допущения.
C21: Штат ухода и начисления рассчитаны на вкладке «Помесячно».
C22: Руководитель ухода 5/2 не является круглосуточной медсестрой.
C23: Прачечная — внешний подряд, затраты в переменных расходах.
C24: Фактическое число сотрудников и график утверждаются до открытия.

Sheet Инвестиции
C2: Инвестиции и финансирование
C4: Сценарий | D4: =Параметры!E5 -> Базовый
C7: Позиция | D7: Количество | E7: Ед. | F7: Цена, ₽ | G7: Сумма, ₽
C8: Кровать механическая | D8: =Параметры!D10/2 -> 30 | E8: шт. | F8: 39900 | G8: =D8*F8 -> 1197000 | I8: https://www.met.ru/goods/19563/
C9: Кровать электрическая | D9: =Параметры!D10/2 -> 30 | E9: шт. | F9: 55900 | G9: =D9*F9 -> 1677000 | I9: https://www.met.ru/goods/18001/
C10: Матрас с мембранным чехлом | D10: =Параметры!D10 -> 60 | E10: шт. | F10: 24900 | G10: =D10*F10 -> 1494000 | I10: https://www.met.ru/goods/18898/
C11: Тумба, шкаф, текстиль | D11: =Параметры!D10 -> 60 | E11: компл. | F11: 25000 | G11: =D11*F11 -> 1500000 | I11: Бюджетное допущение
C12: Мобильный подъемник пациента | D12: 2 | E12: шт. | F12: 79900 | G12: =D12*F12 -> 159800 | I12: https://www.met.ru/goods/18656/
C13: Кресло-туалет | D13: 10 | E13: шт. | F13: 6900 | G13: =D13*F13 -> 69000 | I13: https://www.met.ru/goods/21310/
C14: Противопролежневая система | D14: 10 | E14: шт. | F14: 16900 | G14: =D14*F14 -> 169000 | I14: https://www.met.ru/goods/19599/
C15: Мебель общих зон | D15: 1 | E15: компл. | F15: 900000 | G15: =D15*F15 -> 900000 | I15: Бюджетное допущение
C16: Оснащение кухни | D16: 1 | E16: компл. | F16: 1200000 | G16: =D16*F16 -> 1200000 | I16: Бюджетное допущение
C17: Вызов персонала | D17: 1 | E17: компл. | F17: 650000 | G17: =D17*F17 -> 650000 | I17: Бюджетное допущение
C18: IT и видеонаблюдение | D18: 1 | E18: компл. | F18: 400000 | G18: =D18*F18 -> 400000 | I18: Бюджетное допущение
C19: Служебная мебель | D19: 1 | E19: компл. | F19: 300000 | G19: =D19*F19 -> 300000 | I19: Бюджетное допущение
C20: Прочее оснащение | D20: 1 | E20: компл. | F20: 400000 | G20: =D20*F20 -> 400000 | I20: Бюджетное допущение
C21: Изолятор: 2 койки с оснащением | D21: 2 | E21: компл. | F21: 105800 | G21: =D21*F21 -> 211600 | I21: 2 отдельные палаты вне продаваемой вместимости.
C22: Оснащение до резерва | G22: =SUM(G8:G21) -> 10327400
C23: Резерв оснащения | F23: 0.15 | G23: =G22*F23 -> 1549110
C24: Оснащение с резервом | G24: =SUM(G22:G23) -> 11876510
C26: Предпусковые расходы | G26: 2000000
C27: Первоначальный запас | G27: 350000
C28: Возвратный депозит аренды | D28: 2 | F28: =Параметры!D41 -> 1290170 | G28: =D28*F28 -> 2580340
C30: Невозвратные первоначальные расходы | G30: =SUM(G24,G26) -> 13876510
C31: Учтённые вложения без ремонта | G31: =SUM(G30,G27:G28) -> 16806850
C32: Ликвидность на счете при открытии | G32: =Параметры!D63 -> 8000000
C33: Финансирование без ремонта с резервом | G33: =SUM(G31:G32) -> 24806850
C36: Резерв ликвидности не является расходом.
C37: Депозит и запас включены один раз. Возврат при выходе не моделируется.
C38: Ремонт и реконструкция полностью вне этого бюджета: отдельная смета.
C39: Подъемник пациента не заменяет межэтажный лифт.
C40: Амортизация только оснащения с резервом: условно 60 месяцев.
C41: Дополнительно 2 изоляционные койки вне постоянных мест.
